<!--
  Copyright 2016 The Cartographer Authors

  Licensed under the Apache License, Version 2.0 (the "License");
  you may not use this file except in compliance with the License.
  You may obtain a copy of the License at

       http://www.apache.org/licenses/LICENSE-2.0

  Unless required by applicable law or agreed to in writing, software
  distributed under the License is distributed on an "AS IS" BASIS,
  WITHOUT WARRANTIES OR CONDITIONS OF ANY KIND, either express or implied.
  See the License for the specific language governing permissions and
  limitations under the License.

  Reference:
   [1] https://github.com/IntelRealSense/librealsense/blob/master/doc/d435i.md

-->

<robot name="thu_scout_mini">
  <material name="orange">
    <color rgba="1.0 0.5 0.2 1" />
  </material>
  <material name="gray">
    <color rgba="0.2 0.2 0.2 1" />
  </material>
  <material name="black">
    <color rgba="0.0 0.0 0.0 1" />
  </material>
  <material name="white">
    <color rgba="1.0 1.0 1.0 1" />
  </material>

  <!-- VLP-16 -->
  <link name="velodyne">
    <visual>
      <origin xyz="0.0 0.0 0.0" />
      <geometry>
        <cylinder length="0.07" radius="0.05" />
      </geometry>
      <material name="orange" />
    </visual>
  </link>

  <!-- Azure Kinet DK -->
  <link name = "kinect">
    <visual>
      <origin xyz="0.0 0.0 0.0" />
      <geometry>
        <box size="0.127 0.103 0.026" />
      </geometry>
      <material name="gray" />
    </visual>
  </link>

  <!-- ZED stereo camera -->
  <link name = "zed">
    <visual>
      <origin xyz="0.0 0.0 0.0" />
      <geometry>
        <box size="0.032 0.172 0.028" />
      </geometry>
      <material name="gray" />
    </visual>
  </link>

  <!-- IPC -->
  <link name = "ipc">
    <visual>
      <origin xyz="0.0 0.0 0.0" />
      <geometry>
        <box size="0.225 0.205 0.12" />
      </geometry>
      <material name="black" />
    </visual>
  </link>

  <!-- imu -->
  <link name="imu">
    <visual>
      <origin xyz="0.0 0.0 0.0" />
      <geometry>
        <cylinder length="0.027" radius="0.03" />
      </geometry>
      <material name="orange" />
    </visual>
  </link>


  <link name="base_link">
    <visual>
      <origin xyz="0.0 0.0 0.17" />
      <geometry>
        <box size="0.57 0.40 0.12" />
      </geometry>
      <material name="white" />
    </visual>
    <collision>
      <geometry>
        <box size="0.63 0.63 0.7" />
      </geometry>
    </collision>
    <inertial>
      <mass value="30" />
      <inertia ixx="0.6" ixy="0.0" ixz="0.0" iyy="0.6" iyz="0.0" izz="0.3"/>
    </inertial>
  </link>

  <link name="front_left_wheel">
    <visual>
      <origin xyz="0.0 0.0 0.0" rpy="1.57075 0 0" />
      <geometry>
        <cylinder length="0.08" radius="0.08" />
      </geometry>
      <material name="black" />
    </visual>
  </link>
  <link name="front_right_wheel">
    <visual>
      <origin xyz="0.0 0.0 0.0" rpy="1.57075 0 0" />
      <geometry>
        <cylinder length="0.08" radius="0.08" />
      </geometry>
      <material name="black" />
    </visual>
  </link>
  <link name="rear_left_wheel">
    <visual>
      <origin xyz="0.0 0.0 0.0" rpy="1.57075 0 0" />
      <geometry>
        <cylinder length="0.08" radius="0.08" />
      </geometry>
      <material name="black" />
    </visual>
  </link>
  <link name="rear_right_wheel">
    <visual>
      <origin xyz="0.0 0.0 0.0" rpy="1.57075 0 0" />
      <geometry>
        <cylinder length="0.08" radius="0.08" />
      </geometry>
      <material name="black" />
    </visual>
  </link>

  <joint name="velodyne_joint" type="fixed">
    <parent link="base_link" />
    <child link="velodyne" />
    <origin xyz="0.02 0.0 0.645" rpy="0 0 0" />
  </joint>

  <joint name="imu_joint" type="fixed">
    <parent link="base_link" />
    <child link="imu" />
    <origin xyz="0 0 0.4335" rpy="0 0 0" />
  </joint>

<joint name="ipc_joint" type="fixed">
    <parent link="base_link" />
    <child link="ipc" />
    <origin xyz="0 0 0.3" rpy="0 0 0" />
  </joint>

  <joint name="kinect_joint" type="fixed">
    <parent link="base_link" />
    <child link="kinect" />
    <origin xyz="0.1085 0 0.555" rpy="0 0 0" />
  </joint>

  <joint name="zed_joint" type="fixed">
    <parent link="base_link" />
    <child link="zed" />
    <origin xyz="0.24 0 0.455" rpy="0 0 0" />
  </joint>

  <joint name="front_left_wheel_joint" type="continuous">
    <parent link="base_link" />
    <child link="front_left_wheel" />
    <axis rpy="0 0 0" xyz="0 1 0"/>
    <origin xyz="0.235 0.255 0.08" rpy="0 0 0" />
  </joint>
  
  <joint name="front_right_wheel_joint" type="continuous">
    <parent link="base_link" />
    <child link="front_right_wheel" />
    <axis rpy="0 0 0" xyz="0 1 0"/>
    <origin xyz="0.235 -0.255 0.08" rpy="0 0 0" />
  </joint>

  <joint name="rear_left_wheel_joint" type="continuous">
    <parent link="base_link" />
    <child link="rear_left_wheel" />
    <axis rpy="0 0 0" xyz="0 1 0"/>
    <origin xyz="-0.235 0.255 0.08" rpy="0 0 0" />
  </joint>
  
  <joint name="rear_right_wheel_joint" type="continuous">
    <parent link="base_link" />
    <child link="rear_right_wheel" />
    <axis rpy="0 0 0" xyz="0 1 0"/>
    <origin xyz="-0.235 -0.255 0.08" rpy="0 0 0" />
  </joint>

  <gazebo>
  <plugin name="gazebo_ros_control" filename="libgazebo_ros_control.so">
    <robotNamespace>/</robotNamespace>
  </plugin>
  </gazebo>
</robot>
